Workbook

Sheet Matches-results-bets-points
B1: Time | C1: Match | D1: Result | E1: Aimar | F1: pts | G1: Avo | H1: pts | I1: Hania | J1: pts | K1: Herbert | L1: pts | M1: Janusz | N1: pts | O1: Jaś | P1: pts | Q1: Joanna & Adam | R1: pts | S1: Magda & Krzysiek | T1: pts | U1: Mihkel | V1: pts | W1: Ola & Kaur | X1: pts | Y1: Olle & Kätlin | Z1: pts | AA1: Paweł | AB1: pts | AC1: Piotrek | AD1: pts | AE1: Przemek | AF1: pts | AG1: Sebastian | AH1: pts | AI1: Timo | AJ1: pts
A2: Thu 11.06 | B2: 21.00 | C2: Mexico - South Africa | D2: 2 : 0 | E2: 2 : 0 | F2: 2 | G2: 1 : 0 | H2: 1 | I2: 3 : 1 | J2: 1 | K2: 2 : 0 | L2: 2 | M2: 2 : 0 | N2: 2 | O2: 1 : 0 | P2: 1 | Q2: 2 : 0 | R2: 2 | S2: 2 : 1 | T2: 1 | U2: 2 : 0 | V2: 2 | W2: 1 : 1 | Y2: 1 : 0 | Z2: 1 | AA2: 3 : 0 | AB2: 1 | AC2: 3 : 1 | AD2: 1 | AE2: 3 : 1 | AF2: 1 | AG2: 3 : 1 | AH2: 1 | AI2: 2 : 1 | AJ2: 1
A3: Fri 12.06 | B3: 04.00 | C3: Korea Republic - Czechia | D3: 2 : 1 | E3: 1 : 1 | G3: 1 : 2 | I3: 1 : 3 | K3: 0 : 1 | M3: 1 : 1 | O3: 1 : 2 | Q3: 0 : 1 | S3: 1 : 1 | U3: 1 : 0 | V3: 1 | W3: 1 : 2 | Y3: 0 : 2 | AA3: 1 : 1 | AC3: 0 : 0 | AE3: 1 : 2 | AG3: 2 : 1 | AH3: 2 | AI3: 0 : 3
B4: 21.00 | C4: Canada - Bosnia | D4: 1 : 1 | E4: 2 : 0 | G4: 0 : 1 | I4: 2 : 0 | K4: 1 : 0 | M4: 1 : 1 | N4: 2 | O4: 2 : 1 | Q4: 1 : 0 | S4: 1 : 0 | U4: 1 : 0 | W4: 1 : 1 | X4: 2 | Y4: 2 : 1 | AA4: 2 : 1 | AC4: 1 : 1 | AD4: 2 | AE4: 2 : 0 | AG4: 2 : 0 | AI4: 0 : 2
A5: Sat 13.06 | B5: 03.00 | C5: USA - Paraguay | D5: 4 : 1 | E5: 1 : 0 | F5: 1 | G5: 2 : 0 | H5: 1 | I5: 3 : 0 | J5: 1 | K5: 2 : 1 | L5: 1 | M5: 1 : 0 | N5: 1 | O5: 1 : 0 | P5: 1 | Q5: 1 : 0 | R5: 1 | S5: 2 : 0 | T5: 1 | U5: 2 : 1 | V5: 1 | W5: 3 : 1 | X5: 1 | Y5: 2 : 0 | Z5: 1 | AA5: 2 : 1 | AB5: 1 | AC5: 1 : 0 | AD5: 1 | AE5: 2 : 1 | AF5: 1 | AG5: 2 : 1 | AH5: 1 | AI5: 1 : 2
B6: 21.00 | C6: Qatar - Switzerland | D6: 1 : 1 | E6: 0 : 2 | G6: 0 : 2 | I6: 2 : 2 | J6: 1 | K6: 0 : 2 | M6: 0 : 2 | O6: 0 : 2 | Q6: 0 : 2 | S6: 1 : 2 | U6: 0 : 3 | W6: 1 : 3 | Y6: 0 : 2 | AA6: 0 : 3 | AC6: 0 : 2 | AE6: 0 : 2 | AG6: 0 : 3 | AI6: 0 : 3
A7: Sun 14.06 | B7: 00.00 | C7: Brazil - Morocco | D7: 1 : 1 | E7: 2 : 1 | G7: 2 : 1 | I7: 3 : 1 | K7: 3 : 0 | M7: 2 : 1 | O7: 2 : 1 | Q7: 2 : 0 | S7: 3 : 2 | U7: 2 : 1 | W7: 2 : 1 | Y7: 3 : 0 | AA7: 2 : 1 | AC7: 2 : 1 | AE7: 4 : 0 | AG7: 2 : 2 | AH7: 1 | AI7: 2 : 0
B8: 03.00 | C8: Hailti - Scotland | D8: 0 : 1 | E8: 0 : 2 | F8: 1 | G8: 1 : 0 | I8: 0 : 3 | J8: 1 | K8: 0 : 2 | L8: 1 | M8: 0 : 2 | N8: 1 | O8: 1 : 1 | Q8: 1 : 2 | R8: 1 | S8: 0 : 1 | T8: 2 | U8: 0 : 2 | V8: 1 | W8: 0 : 2 | X8: 1 | Y8: 0 : 2 | Z8: 1 | AA8: 0 : 0 | AC8: 1 : 3 | AD8: 1 | AE8: 0 : 2 | AF8: 1 | AG8: 0 : 2 | AH8: 1 | AI8: 0 : 1 | AJ8: 2
B9: 06.00 | C9: Australia - Turkiye | D9: 2 : 0 | E9: 1 : 2 | G9: 0 : 2 | I9: 1 : 1 | K9: 1 : 1 | M9: 0 : 2 | O9: 0 : 1 | Q9: 0 : 1 | S9: 1 : 3 | U9: 0 : 1 | W9: 0 : 2 | Y9: 1 : 2 | AA9: 1 : 1 | AC9: 1 : 1 | AE9: 1 : 3 | AG9: 0 : 3 | AI9: 1 : 2
B10: 19.00 | C10: Germany - Curacao | D10: 7 : 1 | E10: 3 : 0 | F10: 1 | G10: 3 : 0 | H10: 1 | I10: 6 : 0 | J10: 1 | K10: 4 : 0 | L10: 1 | M10: 3 : 0 | N10: 1 | O10: 2 : 0 | P10: 1 | Q10: 5 : 0 | R10: 1 | S10: 3 : 0 | T10: 1 | U10: 4 : 0 | V10: 1 | W10: 3 : 0 | X10: 1 | Y10: 3 : 0 | Z10: 1 | AA10: 1 : 0 | AB10: 1 | AC10: 4 : 0 | AD10: 1 | AE10: 5 : 0 | AF10: 1 | AG10: 6 : 0 | AH10: 1 | AI10: 3 : 0 | AJ10: 1
B11: 22.00 | C11: Netherlands - Japan | D11: 2 : 2 | E11: 2 : 1 | G11: 2 : 1 | I11: 2 : 1 | K11: 2 : 0 | M11: 1 : 1 | N11: 1 | O11: 2 : 1 | Q11: 2 : 1 | S11: 2 : 2 | T11: 2 | U11: 2 : 1 | W11: 2 : 1 | Y11: 2 : 1 | AA11: 2 : 1 | AC11: 2 : 1 | AE11: 1 : 0 | AG11: 1 : 2 | AI11: 1 : 1 | AJ11: 1
A12: Mon 15.06 | B12: 01.00 | C12: Ivory Coast - Ecuador | D12: 1 : 0 | E12: 0 : 1 | G12: 1 : 1 | I12: 1 : 3 | K12: 1 : 1 | M12: 2 : 1 | N12: 1 | O12: 1 : 1 | Q12: 1 : 1 | S12: 1 : 1 | U12: 1 : 1 | W12: 0 : 2 | Y12: 1 : 1 | AA12: 0 : 0 | AC12: 1 : 1 | AE12: 0 : 2 | AG12: 2 : 2 | AI12: 1 : 2
B13: 04.00 | C13: Sweden - Tunisia | D13: 5 : 1 | E13: 2 : 0 | F13: 1 | G13: 0 : 0 | I13: 3 : 0 | J13: 1 | K13: 1 : 0 | L13: 1 | M13: 2 : 0 | N13: 1 | O13: 1 : 1 | Q13: 1 : 0 | R13: 1 | S13: 2 : 0 | T13: 1 | U13: 1 : 0 | V13: 1 | W13: 2 : 0 | X13: 1 | Y13: 1 : 0 | Z13: 1 | AA13: 3 : 0 | AB13: 1 | AC13: 1 : 0 | AD13: 1 | AE13: 2 : 0 | AF13: 1 | AG13: 2 : 0 | AH13: 1 | AI13: 2 : 0 | AJ13: 1
B14: 18.00 | C14: Spain - Cape Verde | D14: 0 : 0 | E14: 3 : 0 | G14: 3 : 0 | I14: 6 : 0 | K14: 3 : 0 | M14: 3 : 0 | O14: 3 : 0 | Q14: 3 : 0 | S14: 3 : 0 | U14: 3 : 0 | W14: 4 : 0 | Y14: 5 : 0 | AA14: 4 : 0 | AC14: 4 : 0 | AE14: 4 : 0 | AG14: 7 : 0 | AI14: 3 : 0
B15: 21.00 | C15: Belgium - Egypt | D15: 1 : 1 | E15: 2 : 1 | G15: 2 : 1 | I15: 4 : 2 | K15: 1 : 0 | M15: 2 : 0 | O15: 2 : 1 | Q15: 2 : 0 | S15: 2 : 0 | U15: 2 : 0 | W15: 1 : 0 | Y15: 3 : 1 | AA15: 2 : 1 | AC15: 2 : 0 | AE15: 2 : 1 | AG15: 4 : 1 | AI15: 2 : 1
A16: Tue 16.06 | B16: 00.00 | C16: Saudi Arabia - Uruguay | D16: 1 : 1 | E16: 0 : 2 | G16: 1 : 1 | H16: 2 | I16: 2 : 2 | J16: 1 | K16: 0 : 2 | M16: 0 : 2 | O16: 1 : 2 | Q16: 0 : 2 | S16: 0 : 2 | U16: 0 : 2 | W16: 0 : 2 | Y16: 0 : 2 | AA16: 1 : 2 | AC16: 0 : 2 | AE16: 1 : 2 | AG16: 0 : 4 | AI16: 0 : 2
B17: 03.00 | C17: Iran - New Zealand | D17: 2 : 2 | E17: 2 : 0 | G17: 0 : 1 | I17: 1 : 1 | J17: 1 | K17: 0 : 1 | M17: 1 : 1 | N17: 1 | O17: 1 : 1 | P17: 1 | Q17: 2 : 0 | S17: 2 : 1 | U17: 2 : 1 | W17: 2 : 0 | Y17: 1 : 1 | Z17: 1 | AA17: 3 : 0 | AC17: 1 : 3 | AE17: 1 : 0 | AG17: 0 : 0 | AH17: 1 | AI17: 1 : 0
B18: 21.00 | C18: France - Senegal | D18: 3 : 1 | E18: 2 : 0 | F18: 1 | G18: 2 : 1 | H18: 1 | I18: 5 : 0 | J18: 1 | K18: 3 : 1 | L18: 2 | M18: 2 : 1 | N18: 1 | O18: 2 : 1 | P18: 1 | Q18: 2 : 0 | R18: 1 | S18: 3 : 1 | T18: 2 | U18: 2 : 1 | V18: 1 | W18: 2 : 0 | X18: 1 | Y18: 2 : 1 | Z18: 1 | AA18: 2 : 0 | AB18: 1 | AC18: 1 : 1 | AE18: 2 : 0 | AF18: 1 | AG18: 4 : 1 | AH18: 1 | AI18: 2 : 1 | AJ18: 1
A19: Wed 17.06 | B19: 00.00 | C19: Iraq - Norway | D19: 1 : 4 | E19: 0 : 2 | F19: 1 | G19: 0 : 3 | H19: 1 | I19: 1 : 1 | K19: 0 : 2 | L19: 1 | M19: 0 : 2 | N19: 1 | O19: 0 : 2 | P19: 1 | Q19: 0 : 1 | R19: 1 | S19: 0 : 2 | T19: 1 | U19: 1 : 2 | V19: 1 | W19: 0 : 2 | X19: 1 | Y19: 0 : 2 | Z19: 1 | AA19: 1 : 1 | AC19: 1 : 3 | AD19: 1 | AE19: 0 : 2 | AF19: 1 | AG19: 0 : 3 | AH19: 1 | AI19: 0 : 3 | AJ19: 1
B20: 03.00 | C20: Argentina - Algeria | D20: 3 : 0 | E20: 2 : 0 | F20: 1 | G20: 2 : 1 | H20: 1 | I20: 4 : 0 | J20: 1 | K20: 3 : 0 | L20: 2 | M20: 2 : 0 | N20: 1 | O20: 3 : 0 | P20: 2 | Q20: 2 : 1 | R20: 1 | S20: 2 : 1 | T20: 1 | U20: 3 : 0 | V20: 2 | W20: 2 : 0 | X20: 1 | Y20: 2 : 0 | Z20: 1 | AA20: 3 : 0 | AB20: 2 | AC20: 1 : 0 | AD20: 1 | AE20: 3 : 0 | AF20: 2 | AG20: 2 : 1 | AH20: 1 | AI20: 2 : 2
B21: 06.00 | C21: Austria - Jordan | D21: 3 : 1 | E21: 2 : 0 | F21: 1 | G21: 2 : 0 | H21: 1 | I21: 3 : 0 | J21: 1 | K21: 1 : 0 | L21: 1 | M21: 2 : 0 | N21: 1 | O21: 1 : 0 | P21: 1 | Q21: 1 : 0 | R21: 1 | S21: 3 : 0 | T21: 1 | U21: 2 : 0 | V21: 1 | W21: 1 : 0 | X21: 1 | Y21: 1 : 0 | Z21: 1 | AA21: 0 : 0 | AC21: 2 : 0 | AD21: 1 | AE21: 2 : 1 | AF21: 1 | AG21: 4 : 0 | AH21: 1 | AI21: 2 : 0 | AJ21: 1
B22: 19.00 | C22: Portugal - Congo DR | D22: 1 : 1 | E22: 2 : 0 | G22: 2 : 1 | I22: 5 : 1 | K22: 2 : 0 | M22: 2 : 0 | O22: 2 : 0 | Q22: 2 : 0 | S22: 3 : 1 | U22: 2 : 0 | W22: 2 : 0 | Y22: 3 : 0 | AA22: 3 : 0 | AC22: 3 : 1 | AE22: 2 : 0 | AG22: 3 : 0 | AI22: 3 : 0
B23: 22.00 | C23: England - Croatia | D23: 4 : 2 | E23: 1 : 1 | G23: 1 : 0 | H23: 1 | I23: 2 : 2 | K23: 1 : 0 | L23: 1 | M23: 1 : 1 | O23: 2 : 2 | Q23: 1 : 0 | R23: 1 | S23: 2 : 1 | T23: 1 | U23: 2 : 1 | V23: 1 | W23: 1 : 0 | X23: 1 | Y23: 2 : 1 | Z23: 1 | AA23: 2 : 2 | AC23: 1 : 1 | AE23: 3 : 0 | AF23: 1 | AG23: 2 : 0 | AH23: 1 | AI23: 2 : 1 | AJ23: 1
A24: Thu 18.06 | B24: 01.00 | C24: Ghana - Panama | D24: 1 : 0 | E24: 1 : 1 | G24: 1 : 0 | H24: 2 | I24: 2 : 2 | K24: 1 : 1 | M24: 1 : 0 | N24: 2 | O24: 1 : 0 | P24: 2 | Q24: 1 : 1 | S24: 1 : 1 | U24: 2 : 1 | V24: 1 | W24: 0 : 1 | Y24: 1 : 1 | AA24: 1 : 1 | AC24: 1 : 1 | AE24: 1 : 2 | AG24: 3 : 1 | AH24: 1 | AI24: 2 : 1 | AJ24: 1
B25: 04.00 | C25: Uzbekistan - Colombia | D25: 1 : 3 | E25: 0 : 2 | F25: 1 | G25: 0 : 2 | H25: 1 | I25: 1 : 2 | J25: 1 | K25: 0 : 2 | L25: 1 | M25: 0 : 2 | N25: 1 | O25: 1 : 2 | P25: 1 | Q25: 0 : 2 | R25: 1 | S25: 1 : 3 | T25: 2 | U25: 1 : 2 | V25: 1 | W25: 0 : 2 | X25: 1 | Y25: 0 : 2 | Z25: 1 | AA25: 0 : 0 | AC25: 0 : 1 | AD25: 1 | AE25: 0 : 2 | AF25: 1 | AG25: 0 : 4 | AH25: 1 | AI25: 0 : 2 | AJ25: 1
B26: 18.00 | C26: Czechia - South Africa | D26: 1 : 1 | E26: 1 : 1 | F26: 2 | G26: 1 : 0 | I26: 2 : 1 | K26: 1 : 0 | M26: 2 : 1 | O26: 2 : 1 | Q26: 1 : 0 | S26: 2 : 1 | U26: 1 : 0 | W26: 1 : 0 | Y26: 2 : 1 | AA26: 2 : 1 | AC26: 2 : 1 | AE26: 2 : 0 | AG26: 2 : 0 | AI26: 2 : 1
B27: 21.00 | C27: Switzerland - Bosnia | D27: 4 : 1 | E27: 1 : 0 | F27: 1 | G27: 1 : 1 | I27: 1 : 1 | K27: 1 : 0 | L27: 1 | M27: 1 : 1 | O27: 1 : 1 | Q27: 1 : 1 | S27: 1 : 0 | T27: 1 | U27: 1 : 1 | W27: 1 : 0 | X27: 1 | Y27: 2 : 1 | Z27: 1 | AA27: 2 : 1 | AB27: 1 | AC27: 1 : 1 | AE27: 1 : 1 | AG27: 0 : 1 | AI27: 1 : 1
A28: Fri 19.06 | B28: 00.00 | C28: Canada - Qatar | D28: 6 : 0 | E28: 2 : 0 | F28: 1 | G28: 2 : 0 | H28: 1 | I28: 2 : 1 | J28: 1 | K28: 2 : 0 | L28: 1 | M28: 2 : 0 | N28: 1 | O28: 2 : 1 | P28: 1 | Q28: 2 : 1 | R28: 1 | S28: 1 : 1 | U28: 2 : 1 | V28: 1 | W28: 1 : 0 | X28: 1 | Y28: 2 : 0 | Z28: 1 | AA28: 2 : 1 | AB28: 1 | AC28: 3 : 1 | AD28: 1 | AE28: 1 : 0 | AF28: 1 | AG28: 1 : 1 | AI28: 2 : 0 | AJ28: 1
B29: 03.00 | C29: Mexico - Korea Republic | D29: 1 : 0 | E29: 1 : 1 | G29: 1 : 2 | I29: 2 : 2 | K29: 1 : 1 | M29: 1 : 1 | O29: 1 : 1 | Q29: 2 : 1 | R29: 1 | S29: 2 : 2 | U29: 2 : 1 | V29: 1 | W29: 1 : 0 | X29: 2 | Y29: 1 : 1 | AA29: 2 : 1 | AB29: 1 | AC29: 2 : 1 | AD29: 1 | AE29: 1 : 1 | AG29: 0 : 2 | AI29: 2 : 2
B30: 21.00 | C30: USA - Australia | D30: 2 : 0 | E30: 2 : 0 | F30: 2 | G30: 2 : 0 | H30: 2 | I30: 2 : 1 | J30: 1 | K30: 2 : 1 | L30: 1 | M30: 3 : 1 | N30: 1 | O30: 2 : 1 | P30: 1 | Q30: 2 : 0 | R30: 2 | S30: 2 : 1 | T30: 1 | U30: 2 : 1 | V30: 1 | W30: 2 : 1 | X30: 1 | Y30: 2 : 1 | Z30: 1 | AA30: 2 : 2 | AC30: 1 : 1 | AE30: 2 : 2 | AG30: 3 : 1 | AH30: 1 | AI30: 2 : 1 | AJ30: 1
A31: Sat 20.06 | B31: 00.00 | C31: Scotland - Morocco | D31: 0 : 1 | E31: 0 : 1 | F31: 2 | G31: 1 : 3 | H31: 1 | I31: 1 : 2 | J31: 1 | K31: 1 : 0 | M31: 1 : 2 | N31: 1 | O31: 1 : 2 | P31: 1 | Q31: 1 : 1 | S31: 0 : 2 | T31: 1 | U31: 1 : 2 | V31: 1 | W31: 0 : 1 | X31: 2 | Y31: 1 : 3 | Z31: 1 | AA31: 1 : 2 | AB31: 1 | AC31: 0 : 0 | AE31: 1 : 2 | AF31: 1 | AG31: 0 : 3 | AH31: 1 | AI31: 1 : 2 | AJ31: 1
B32: 02.30 | C32: Brazil - Haiti | D32: 3 : 0 | E32: 3 : 0 | F32: 2 | G32: 4 : 0 | H32: 1 | I32: 3 : 0 | J32: 2 | K32: 2 : 0 | L32: 1 | M32: 2 : 0 | N32: 1 | O32: 3 : 0 | P32: 2 | Q32: 4 : 0 | R32: 1 | S32: 1 : 0 | T32: 1 | U32: 3 : 0 | V32: 2 | W32: 2 : 0 | X32: 1 | Y32: 4 : 0 | Z32: 1 | AA32: 2 : 1 | AB32: 1 | AC32: 2 : 0 | AD32: 1 | AE32: 3 : 0 | AF32: 2 | AG32: 3 : 0 | AH32: 2 | AI32: 3 : 0 | AJ32: 2
B33: 05.00 | C33: Turkiye - Paraguay | D33: 0 : 1 | E33: 1 : 1 | G33: 2 : 0 | I33: 3 : 1 | K33: 2 : 0 | M33: 2 : 1 | O33: 2 : 1 | Q33: 2 : 1 | S33: 2 : 1 | U33: 2 : 1 | W33: 1 : 1 | Y33: 1 : 1 | AA33: 1 : 1 | AC33: 2 : 1 | AE33: 1 : 1 | AG33: 1 : 1 | AI33: 2 : 1
B34: 19.00 | C34: Netherlands - Sweden | D34: 5 : 1 | E34: 2 : 1 | F34: 1 | G34: 2 : 2 | I34: 2 : 2 | K34: 1 : 0 | L34: 1 | M34: 2 : 2 | O34: 1 : 2 | Q34: 2 : 1 | R34: 1 | S34: 3 : 2 | T34: 1 | U34: 2 : 2 | W34: 2 : 2 | Y34: 3 : 1 | Z34: 1 | AA34: 2 : 2 | AC34: 2 : 2 | AE34: 2 : 1 | AF34: 1 | AG34: 2 : 2 | AI34: 2 : 1 | AJ34: 1
B35: 22.00 | C35: Germany - Ivory Coast | D35: 2 : 1 | E35: 2 : 0 | F35: 1 | G35: 3 : 1 | H35: 1 | I35: 4 : 1 | J35: 1 | K35: 2 : 1 | L35: 2 | M35: 2 : 1 | N35: 2 | O35: 4 : 1 | P35: 1 | Q35: 2 : 1 | R35: 2 | S35: 3 : 1 | T35: 1 | U35: 2 : 1 | V35: 2 | W35: 3 : 1 | X35: 1 | Y35: 2 : 0 | Z35: 1 | AA35: 3 : 0 | AB35: 1 | AC35: 3 : 1 | AD35: 1 | AE35: 3 : 0 | AF35: 1 | AG35: 3 : 0 | AH35: 1 | AI35: 3 : 1 | AJ35: 1
A36: Sun 21.06 | B36: 02.00 | C36: Ecuador - Curacao | D36: 0 : 0 | E36: 2 : 0 | G36: 1 : 0 | I36: 2 : 2 | J36: 1 | K36: 2 : 0 | M36: 2 : 0 | O36: 2 : 1 | Q36: 2 : 0 | S36: 2 : 1 | U36: 2 : 0 | W36: 2 : 0 | Y36: 2 : 0 | AA36: 2 : 0 | AC36: 2 : 1 | AE36: 2 : 0 | AG36: 0 : 0 | AH36: 2 | AI36: 2 : 0
B37: 06.00 | C37: Tunisia - Japan | D37: 0 : 4 | E37: 0 : 1 | F37: 1 | G37: 0 : 2 | H37: 1 | I37: 1 : 3 | J37: 1 | K37: 0 : 1 | L37: 1 | M37: 0 : 2 | N37: 1 | O37: 1 : 2 | P37: 1 | Q37: 0 : 1 | R37: 1 | S37: 0 : 2 | T37: 1 | U37: 1 : 2 | V37: 1 | W37: 1 : 2 | X37: 1 | Y37: 0 : 1 | Z37: 1 | AA37: 0 : 2 | AB37: 1 | AC37: 0 : 2 | AD37: 1 | AE37: 0 : 2 | AF37: 1 | AG37: 0 : 3 | AH37: 1 | AI37: 1 : 3 | AJ37: 1
B38: 18.00 | C38: Spain - Saudi Arabia | D38: 4 : 0 | E38: 3 : 0 | F38: 1 | G38: 2 : 1 | H38: 1 | I38: 3 : 1 | J38: 1 | K38: 3 : 1 | L38: 1 | M38: 2 : 0 | N38: 1 | O38: 1 : 0 | P38: 1 | Q38: 3 : 0 | R38: 1 | S38: 2 : 1 | T38: 1 | U38: 2 : 0 | V38: 1 | W38: 3 : 1 | X38: 1 | Y38: 5 : 0 | Z38: 1 | AA38: 2 : 0 | AB38: 1 | AC38: 3 : 0 | AD38: 1 | AE38: 3 : 0 | AF38: 1 | AG38: 3 : 1 | AH38: 1 | AI38: 2 : 0 | AJ38: 1
B39: 21.00 | C39: Belgium - Iran | D39: 0 : 0 | E39: 2 : 0 | G39: 3 : 0 | I39: 1 : 0 | K39: 1 : 0 | M39: 2 : 0 | O39: 2 : 1 | Q39: 2 : 0 | S39: 1 : 1 | T39: 1 | U39: 1 : 1 | V39: 1 | W39: 2 : 1 | Y39: 2 : 1 | AA39: 2 : 1 | AC39: 2 : 1 | AE39: 2 : 1 | AG39: 4 : 0 | AI39: 2 : 0
A40: Mon 22.06 | B40: 00.00 | C40: Uruguay - Cape Verde | D40: 2 : 2 | E40: 1 : 0 | G40: 2 : 1 | I40: 1 : 1 | J40: 1 | K40: 1 : 1 | L40: 1 | M40: 1 : 1 | N40: 1 | O40: 2 : 1 | Q40: 2 : 0 | S40: 2 : 0 | U40: 2 : 0 | W40: 1 : 2 | Y40: 2 : 0 | AA40: 2 : 0 | AC40: 2 : 0 | AE40: 2 : 0 | AG40: 2 : 0 | AI40: 2 : 1
...

Sheet Score table
A1: ETV | B1: ETV2
A2: 0.92361111 | F2: Score table (Klasyfikacja graczy) | H2: World champion | I2: Accurate hits | J2: Prize
A3: 0.78125 | E3: 1 | F3: Aimar | G3: ='Matches-results-bets-points'!F107 -> 84 | I3: ='Matches-results-bets-points'!E108 -> 18 | J3: 94 euro
E4: 2 | F4: Janusz | G4: ='Matches-results-bets-points'!N107 -> 82 | I4: ='Matches-results-bets-points'!M108 -> 12 | J4: 300 PLN
E5: 3 | F5: Piotrek | G5: ='Matches-results-bets-points'!AD107 -> 74 | I5: ='Matches-results-bets-points'!AC108 -> 10 | J5: 200 PLN
A6: 0.034722222 | B6: 0.51736111 | E6: 4 | F6: Sebastian | G6: ='Matches-results-bets-points'!AH107 -> 74 | I6: ='Matches-results-bets-points'!AG108 -> 9 | J6: 150 PLN
E7: 5 | F7: Joanna & Adam | G7: ='Matches-results-bets-points'!R107 -> 73 | H7: Spain | I7: ='Matches-results-bets-points'!Q108 -> 11 | J7: 125 PLN
E8: 6 | F8: Herbert | G8: ='Matches-results-bets-points'!L107 -> 73 | I8: ='Matches-results-bets-points'!K108 -> 12 | J8: 23 euro
A9: 0.78125 | E9: 7 | F9: Mihkel | G9: ='Matches-results-bets-points'!V107 -> 73 | I9: ='Matches-results-bets-points'!U108 -> 11
A10: 0.90277778 | E10: 8 | F10: Paweł | G10: ='Matches-results-bets-points'!AB107 -> 72 | I10: ='Matches-results-bets-points'!AA108 -> 13
A11: 0.15972222 | B11: 0.59375 | E11: 9 | F11: Avo | G11: ='Matches-results-bets-points'!H107 -> 72 | I11: ='Matches-results-bets-points'!G108 -> 10
A12: 0.034722222 | B12: 0.52083333 | E12: 10 | F12: Timo | G12: ='Matches-results-bets-points'!AJ107 -> 71 | I12: ='Matches-results-bets-points'!AI108 -> 10
A13: 0.78125 | E13: 11 | F13: Ola & Kaur | G13: ='Matches-results-bets-points'!X107 -> 70 | I13: ='Matches-results-bets-points'!W108 -> 8
E14: 12 | F14: Olle & Kätlin | G14: ='Matches-results-bets-points'!Z107 -> 70 | I14: ='Matches-results-bets-points'!Y108 -> 7
E15: 13 | F15: Magda & Krzysiek | G15: ='Matches-results-bets-points'!T107 -> 69 | I15: ='Matches-results-bets-points'!S108 -> 8
A16: 0.034722222 | B16: 0.51041667 | E16: 14 | F16: Jaś | G16: ='Matches-results-bets-points'!P107 -> 66 | I16: ='Matches-results-bets-points'!O108 -> 4
E17: 15 | F17: Przemek | G17: ='Matches-results-bets-points'!AF107 -> 64 | I17: ='Matches-results-bets-points'!AE108 -> 7
A18: 0.034722222 | B18: 0.50694444 | E18: 16 | F18: Hania | G18: ='Matches-results-bets-points'!J107 -> 54 | I18: ='Matches-results-bets-points'!I108 -> 2
A19: 0.90277778
A23: 0.034722222 | B23: 0.55208333
A24: 0.78125
A25: 0.78125
A26: 0.90277778
A27: 0.034722222 | B27: 0.52083333
A29: 0.78125
A30: 0.90277778
A31: 0.034722222 | B31: 0.57638889
A33: 0.78125
A34: 0.90625

Sheet Schedule of cup phase
A1: Schedule of cup phase (Drabinka fazy pucharowej)
A2: Date | B2: Match
A3: 1/16-finals
A4: 28.06 | B4: match 73 : 2A - 2B
A5: 29.06 | B5: match 74 : 1C - 2F
B6: match 75 : 1E - 3ABCDF
A7: 30.06 | B7: match 76 :1F - 2C
B8: match 77 : 2E - 2I
B9: match 78 : 1I - 3CDFGH
A10: 1.07 | B10: match 79 : 1A - 3CEFHI
B11: match 80 : 1L - 3EHIJK
B12: match 81 : 1G - 3AEHIJ
A13: 2.07 | B13: match 82 : 1D - 3BEFIJ
B14: match 83 : 1H - 2J
A15: 3.07 | B15: match 84 : 2K - 2L
B16: match 85 : 1B - 3EFGIJ
B17: match 86 : 2D - 2G
A18: 4.07 | B18: match 87 : 1J - 2H
B19: match 88 : 1K - 3DEIJL
A20: 1/8-finals
A21: 4.07 | B21: match 89 : winner of 73 - winner of 76
B22: match 90 : winner of 75 - winner of 78
A23: 5.07 | B23: match 91 : winner of 74 - winner of 77
A24: 6.07 | B24: match 92 : winner of 79 - winner of 80
B25: match 93 : winner of 84 - winner of 83
A26: 7.07 | B26: match 94 : winner of 82 - winner of 81
B27: match 95 : winner of 87 - winner of 86
B28: match 96 : winner of 85 - winner of 88
A29: 1/4-finals
A30: 9.07 | B30: match 97 : winner of 90 - winner of 89
A31: 10.07 | B31: match 98 : winner of 93 - winner of 94
A32: 11.07 | B32: match 99 : winner of 91 - winner of 92
A33: 12.07 | B33: match 100 : winner of 95 - winner of 96
A34: 1/2-finals
A35: 14.07 | B35: match 101 : winner of 97 - winner of 98
A36: 15.07 | B36: match 102 : winner of 99 - winner of 100
A37: for third place
A38: 18.07 | B38: defeated in 101 - defeated in 102
A39: final
A40: 19.07 | B40: winner of 101 - winner of 102
